<sdf version='1.4'>
  <world name='default'>
    <model name='ground_plane'>
      <static>1</static>
      <link name='link'>
        <collision name='collision'>
          <geometry>
            <plane>
              <normal>0.000000 0.000000 1.000000</normal>
              <size>100.000000 100.000000</size>
            </plane>
          </geometry>
          <surface>
            <friction>
              <ode>
                <mu>100.000000</mu>
                <mu2>50.000000</mu2>
              </ode>
            </friction>
            <bounce/>
            <contact>
              <ode/>
            </contact>
          </surface>
          <max_contacts>10</max_contacts>
        </collision>
        <visual name='visual'>
          <cast_shadows>0</cast_shadows>
          <geometry>
            <plane>
              <normal>0.000000 0.000000 1.000000</normal>
              <size>100.000000 100.000000</size>
            </plane>
          </geometry>
          <material>
            <script>
              <uri>file://media/materials/scripts/gazebo.material</uri>
              <name>Gazebo/Grey</name>
            </script>
          </material>
        </visual>
        <velocity_decay>
          <linear>0.000000</linear>
          <angular>0.000000</angular>
        </velocity_decay>
        <self_collide>0</self_collide>
        <kinematic>0</kinematic>
        <gravity>1</gravity>
      </link>
    </model>
    <model name='pioneer2dx'>
      <link name='chassis'>
        <pose>0.000000 0.000000 0.160000 0.000000 0.000000 0.000000</pose>
        <inertial>
          <mass>15.000000</mass>
          <inertia>
            <ixx>1.000000</ixx>
            <ixy>0.000000</ixy>
            <ixz>0.000000</ixz>
            <iyy>1.000000</iyy>
            <iyz>0.000000</iyz>
            <izz>1.000000</izz>
          </inertia>
        </inertial>
        <collision name='collision'>
          <geometry>
            <box>
              <size>0.445000 0.277000 0.170000</size>
            </box>
          </geometry>
          <max_contacts>10</max_contacts>
          <surface>
            <bounce/>
            <friction>
              <ode/>
            </friction>
            <contact>
              <ode/>
            </contact>
          </surface>
        </collision>
        <collision name='castor_collision'>
          <pose>-0.200000 0.000000 -0.120000 0.000000 0.000000 0.000000</pose>
          <geometry>
            <sphere>
              <radius>0.040000</radius>
            </sphere>
          </geometry>
          <surface>
            <friction>
              <ode>
                <mu>0.000000</mu>
                <mu2>0.000000</mu2>
                <slip1>1.000000</slip1>
                <slip2>1.000000</slip2>
              </ode>
            </friction>
            <bounce/>
            <contact>
              <ode/>
            </contact>
          </surface>
          <max_contacts>10</max_contacts>
        </collision>
        <visual name='visual'>
          <pose>0.000000 0.000000 0.040000 0.000000 0.000000 0.000000</pose>
          <geometry>
            <mesh>
              <uri>model://pioneer2dx/meshes/chassis.dae</uri>
            </mesh>
          </geometry>
        </visual>
        <visual name='castor_visual'>
          <pose>-0.200000 0.000000 -0.120000 0.000000 0.000000 0.000000</pose>
          <geometry>
            <sphere>
              <radius>0.040000</radius>
            </sphere>
          </geometry>
          <material>
            <script>
              <uri>file://media/materials/scripts/gazebo.material</uri>
              <name>Gazebo/FlatBlack</name>
            </script>
          </material>
        </visual>
        <velocity_decay>
          <linear>0.000000</linear>
          <angular>0.000000</angular>
        </velocity_decay>
        <self_collide>0</self_collide>
        <kinematic>0</kinematic>
        <gravity>1</gravity>
      </link>
      <link name='right_wheel'>
        <pose>0.100000 -0.170000 0.110000 -0.000000 1.570700 1.570700</pose>
        <inertial>
          <mass>0.100000</mass>
          <inertia>
            <ixx>1.000000</ixx>
            <ixy>0.000000</ixy>
            <ixz>0.000000</ixz>
            <iyy>1.000000</iyy>
            <iyz>0.000000</iyz>
            <izz>1.000000</izz>
          </inertia>
        </inertial>
        <collision name='collision'>
          <geometry>
            <cylinder>
              <radius>0.110000</radius>
              <length>0.050000</length>
            </cylinder>
          </geometry>
          <surface>
            <friction>
              <ode>
                <mu>100000.000000</mu>
                <mu2>100000.000000</mu2>
                <slip1>0.000000</slip1>
                <slip2>0.000000</slip2>
              </ode>
            </friction>
            <bounce/>
            <contact>
              <ode/>
            </contact>
          </surface>
          <max_contacts>10</max_contacts>
        </collision>
        <visual name='visual'>
          <geometry>
            <cylinder>
              <radius>0.110000</radius>
              <length>0.050000</length>
            </cylinder>
          </geometry>
          <material>
            <script>
              <uri>file://media/materials/scripts/gazebo.material</uri>
              <name>Gazebo/FlatBlack</name>
            </script>
          </material>
        </visual>
        <velocity_decay>
          <linear>0.000000</linear>
          <angular>0.000000</angular>
        </velocity_decay>
        <self_collide>0</self_collide>
        <kinematic>0</kinematic>
        <gravity>1</gravity>
      </link>
      <link name='left_wheel'>
        <pose>0.100000 0.170000 0.110000 -0.000000 1.570700 1.570700</pose>
        <inertial>
          <mass>0.500000</mass>
          <inertia>
            <ixx>1.000000</ixx>
            <ixy>0.000000</ixy>
            <ixz>0.000000</ixz>
            <iyy>1.000000</iyy>
            <iyz>0.000000</iyz>
            <izz>1.000000</izz>
          </inertia>
        </inertial>
        <collision name='collision'>
          <geometry>
            <cylinder>
              <radius>0.110000</radius>
              <length>0.050000</length>
            </cylinder>
          </geometry>
          <surface>
            <friction>
              <ode>
                <mu>100000.000000</mu>
                <mu2>100000.000000</mu2>
                <slip1>0.000000</slip1>
                <slip2>0.000000</slip2>
              </ode>
            </friction>
            <bounce/>
            <contact>
              <ode/>
            </contact>
          </surface>
          <max_contacts>10</max_contacts>
        </collision>
        <visual name='visual'>
          <geometry>
            <cylinder>
              <radius>0.110000</radius>
              <length>0.050000</length>
            </cylinder>
          </geometry>
          <material>
            <script>
              <uri>file://media/materials/scripts/gazebo.material</uri>
              <name>Gazebo/FlatBlack</name>
            </script>
          </material>
        </visual>
        <velocity_decay>
          <linear>0.000000</linear>
          <angular>0.000000</angular>
        </velocity_decay>
        <self_collide>0</self_collide>
        <kinematic>0</kinematic>
        <gravity>1</gravity>
      </link>
      <link name='laser'>
        <pose>0.220000 0.000000 0.300000 0.000000 0.000000 0.000000</pose>
        <gravity>0</gravity>
        <inertial>
          <mass>0.100000</mass>
          <inertia>
            <ixx>1.000000</ixx>
            <ixy>0.000000</ixy>
            <ixz>0.000000</ixz>
            <iyy>1.000000</iyy>
            <iyz>0.000000</iyz>
            <izz>1.000000</izz>
          </inertia>
        </inertial>
        <visual name='visual'>
          <geometry>
            <mesh>
              <uri>model://hokuyo/meshes/hokuyo.dae</uri>
            </mesh>
          </geometry>
        </visual>
        <collision name='collision-base'>
          <pose>0.000000 0.000000 -0.014500 0.000000 0.000000 0.000000</pose>
          <geometry>
            <box>
              <size>0.050000 0.050000 0.041000</size>
            </box>
          </geometry>
          <max_contacts>10</max_contacts>
          <surface>
            <bounce/>
            <friction>
              <ode/>
            </friction>
            <contact>
              <ode/>
            </contact>
          </surface>
        </collision>
        <collision name='collision-top'>
          <pose>0.000000 0.000000 0.020500 0.000000 0.000000 0.000000</pose>
          <geometry>
            <cylinder>
              <radius>0.021000</radius>
              <length>0.029000</length>
            </cylinder>
          </geometry>
          <max_contacts>10</max_contacts>
          <surface>
            <bounce/>
            <friction>
              <ode/>
            </friction>
            <contact>
              <ode/>
            </contact>
          </surface>
        </collision>
        <sensor name='laser' type='ray'>
          <update_rate>20.000000</update_rate>
          <ray>
            <scan>
              <horizontal>
                <samples>180</samples>
                <resolution>1.000000</resolution>
                <min_angle>-1.570000</min_angle>
                <max_angle>1.570000</max_angle>
              </horizontal>
            </scan>
            <range>
              <min>0.080000</min>
              <max>10.000000</max>
              <resolution>0.010000</resolution>
            </range>
          </ray>
          <plugin name='laser' filename='liblaser.so'/>
          <always_on>1</always_on>
          <visualize>1</visualize>
        </sensor>
        <velocity_decay>
          <linear>0.000000</linear>
          <angular>0.000000</angular>
        </velocity_decay>
        <self_collide>0</self_collide>
        <kinematic>0</kinematic>
      </link>
      <link name='camera_bottom_body_left'>
        <pose>0.160000 0.100000 0.300000 -1.570000 0.000000 0.000000</pose>
        <inertial>
          <mass>0.500000</mass>
          <inertia>
            <ixx>1.000000</ixx>
            <ixy>0.000000</ixy>
            <ixz>0.000000</ixz>
            <iyy>1.000000</iyy>
            <iyz>0.000000</iyz>
            <izz>1.000000</izz>
          </inertia>
        </inertial>
        <visual name='visual'>
          <geometry>
            <mesh>
              <uri>model://pioneer2dxJde/meshes/sonyvid30/sonyvid30_bottom.dae</uri>
              <scale>4.000000 3.000000 3.000000</scale>
            </mesh>
          </geometry>
        </visual>
        <collision name='collision'>
          <geometry>
            <box>
              <size>0.100000 0.100000 0.100000</size>
            </box>
          </geometry>
          <surface>
            <friction>
              <ode>
                <mu>100000.000000</mu>
                <mu2>100000.000000</mu2>
                <slip1>0.000000</slip1>
                <slip2>0.000000</slip2>
              </ode>
            </friction>
            <bounce/>
            <contact>
              <ode/>
            </contact>
          </surface>
          <max_contacts>10</max_contacts>
        </collision>
        <velocity_decay>
          <linear>0.000000</linear>
          <angular>0.000000</angular>
        </velocity_decay>
        <self_collide>0</self_collide>
        <kinematic>0</kinematic>
        <gravity>1</gravity>
      </link>
      <link name='camera_column_body_left'>
        <pose>0.170000 0.100000 0.315000 -1.570000 0.000000 0.000000</pose>
        <inertial>
          <mass>0.500000</mass>
          <inertia>
            <ixx>1.000000</ixx>
            <ixy>0.000000</ixy>
            <ixz>0.000000</ixz>
            <iyy>1.000000</iyy>
            <iyz>0.000000</iyz>
            <izz>1.000000</izz>
          </inertia>
        </inertial>
        <visual name='visual'>
          <geometry>
            <mesh>
              <uri>model://pioneer2dxJde/meshes/sonyvid30/sonyvid30_mid.dae</uri>
              <scale>0.600000 1.000000 1.000000</scale>
            </mesh>
          </geometry>
        </visual>
        <collision name='collision'>
          <geometry>
            <box>
              <size>0.100000 0.100000 0.100000</size>
            </box>
          </geometry>
          <surface>
            <friction>
              <ode>
                <mu>100000.000000</mu>
                <mu2>100000.000000</mu2>
                <slip1>0.000000</slip1>
                <slip2>0.000000</slip2>
              </ode>
            </friction>
            <bounce/>
            <contact>
              <ode/>
            </contact>
          </surface>
          <max_contacts>10</max_contacts>
        </collision>
        <velocity_decay>
          <linear>0.000000</linear>
          <angular>0.000000</angular>
        </velocity_decay>
        <self_collide>0</self_collide>
        <kinematic>0</kinematic>
        <gravity>1</gravity>
      </link>
      <link name='camera_top_body_left'>
        <pose>0.140000 0.100000 0.310000 -1.570000 -0.000000 3.140000</pose>
        <inertial>
          <mass>0.500000</mass>
          <inertia>
            <ixx>1.000000</ixx>
            <ixy>0.000000</ixy>
            <ixz>0.000000</ixz>
            <iyy>1.000000</iyy>
            <iyz>0.000000</iyz>
            <izz>1.000000</izz>
          </inertia>
        </inertial>
        <sensor name='cam_sensor_left' type='camera'>
          <pose>0.000000 0.000000 0.000000 -1.570000 -0.000000 3.140000</pose>
          <update_rate>20.000000</update_rate>
          <camera name='__default__'>
            <horizontal_fov>1.570000</horizontal_fov>
            <image>
              <width>640</width>
              <height>480</height>
              <format>R8G8B8</format>
            </image>
            <clip>
              <near>0.300000</near>
              <far>15.000000</far>
            </clip>
          </camera>
          <plugin name='camera_dump' filename='libcamera_dump.so'/>
        </sensor>
        <visual name='visual'>
          <geometry>
            <mesh>
              <uri>model://pioneer2dxJde/meshes/sonyvid30/sonyvid30_top.dae</uri>
              <scale>2.000000 2.000000 1.300000</scale>
            </mesh>
          </geometry>
        </visual>
        <collision name='collision'>
          <geometry>
            <box>
              <size>0.100000 0.100000 0.100000</size>
            </box>
          </geometry>
          <surface>
            <friction>
              <ode>
                <mu>100000.000000</mu>
                <mu2>100000.000000</mu2>
                <slip1>0.000000</slip1>
                <slip2>0.000000</slip2>
              </ode>
            </friction>
            <bounce/>
            <contact>
              <ode/>
            </contact>
          </surface>
          <max_contacts>10</max_contacts>
        </collision>
        <velocity_decay>
          <linear>0.000000</linear>
          <angular>0.000000</angular>
        </velocity_decay>
        <self_collide>0</self_collide>
        <kinematic>0</kinematic>
        <gravity>1</gravity>
      </link>
      <link name='camera_bottom_body_right'>
        <pose>0.160000 -0.100000 0.300000 -1.570000 0.000000 0.000000</pose>
        <inertial>
          <mass>0.500000</mass>
          <inertia>
            <ixx>1.000000</ixx>
            <ixy>0.000000</ixy>
            <ixz>0.000000</ixz>
            <iyy>1.000000</iyy>
            <iyz>0.000000</iyz>
            <izz>1.000000</izz>
          </inertia>
        </inertial>
        <visual name='visual'>
          <geometry>
            <mesh>
              <uri>model://pioneer2dxJde/meshes/sonyvid30/sonyvid30_bottom.dae</uri>
              <scale>4.000000 3.000000 3.000000</scale>
            </mesh>
          </geometry>
        </visual>
        <collision name='collision'>
          <geometry>
            <box>
              <size>0.100000 0.100000 0.100000</size>
            </box>
          </geometry>
          <surface>
            <friction>
              <ode>
                <mu>100000.000000</mu>
                <mu2>100000.000000</mu2>
                <slip1>0.000000</slip1>
                <slip2>0.000000</slip2>
              </ode>
            </friction>
            <bounce/>
            <contact>
              <ode/>
            </contact>
          </surface>
          <max_contacts>10</max_contacts>
        </collision>
        <velocity_decay>
          <linear>0.000000</linear>
          <angular>0.000000</angular>
        </velocity_decay>
        <self_collide>0</self_collide>
        <kinematic>0</kinematic>
        <gravity>1</gravity>
      </link>
      <link name='camera_column_body_right'>
        <pose>0.170000 -0.100000 0.315000 -1.570000 0.000000 0.000000</pose>
        <inertial>
          <mass>0.500000</mass>
          <inertia>
            <ixx>1.000000</ixx>
            <ixy>0.000000</ixy>
            <ixz>0.000000</ixz>
            <iyy>1.000000</iyy>
            <iyz>0.000000</iyz>
            <izz>1.000000</izz>
          </inertia>
        </inertial>
        <visual name='visual'>
          <geometry>
            <mesh>
              <uri>model://pioneer2dxJde/meshes/sonyvid30/sonyvid30_mid.dae</uri>
              <scale>0.600000 1.000000 1.000000</scale>
            </mesh>
          </geometry>
        </visual>
        <collision name='collision'>
          <geometry>
            <box>
              <size>0.100000 0.100000 0.100000</size>
            </box>
          </geometry>
          <surface>
            <friction>
              <ode>
                <mu>100000.000000</mu>
                <mu2>100000.000000</mu2>
                <slip1>0.000000</slip1>
                <slip2>0.000000</slip2>
              </ode>
            </friction>
            <bounce/>
            <contact>
              <ode/>
            </contact>
          </surface>
          <max_contacts>10</max_contacts>
        </collision>
        <velocity_decay>
          <linear>0.000000</linear>
          <angular>0.000000</angular>
        </velocity_decay>
        <self_collide>0</self_collide>
        <kinematic>0</kinematic>
        <gravity>1</gravity>
      </link>
      <link name='camera_top_body_right'>
        <pose>0.140000 -0.100000 0.310000 -1.570000 -0.000000 3.140000</pose>
        <inertial>
          <mass>0.500000</mass>
          <inertia>
            <ixx>1.000000</ixx>
            <ixy>0.000000</ixy>
            <ixz>0.000000</ixz>
            <iyy>1.000000</iyy>
            <iyz>0.000000</iyz>
            <izz>1.000000</izz>
          </inertia>
        </inertial>
        <sensor name='cam_sensor_right' type='camera'>
          <pose>0.000000 0.000000 0.000000 -1.570000 -0.000000 3.140000</pose>
          <update_rate>20.000000</update_rate>
          <camera name='__default__'>
            <horizontal_fov>1.570000</horizontal_fov>
            <image>
              <width>640</width>
              <height>480</height>
              <format>R8G8B8</format>
            </image>
            <clip>
              <near>0.300000</near>
              <far>15.000000</far>
            </clip>
          </camera>
          <plugin name='camera_dump' filename='libcamera_dump.so'/>
        </sensor>
        <visual name='visual'>
          <geometry>
            <mesh>
              <uri>model://pioneer2dxJde/meshes/sonyvid30/sonyvid30_top.dae</uri>
              <scale>2.000000 2.000000 1.300000</scale>
            </mesh>
          </geometry>
        </visual>
        <collision name='collision'>
          <geometry>
            <box>
              <size>0.100000 0.100000 0.100000</size>
            </box>
          </geometry>
          <surface>
            <friction>
              <ode>
                <mu>100000.000000</mu>
                <mu2>100000.000000</mu2>
                <slip1>0.000000</slip1>
                <slip2>0.000000</slip2>
              </ode>
            </friction>
            <bounce/>
            <contact>
              <ode/>
            </contact>
          </surface>
          <max_contacts>10</max_contacts>
        </collision>
        <velocity_decay>
          <linear>0.000000</linear>
          <angular>0.000000</angular>
        </velocity_decay>
        <self_collide>0</self_collide>
        <kinematic>0</kinematic>
        <gravity>1</gravity>
      </link>
      <joint name='pan_joint_right' type='revolute'>
        <pose>0.000000 0.000000 0.000000 0.000000 0.000000 0.000000</pose>
        <child>camera_bottom_body_right</child>
        <parent>camera_column_body_right</parent>
        <axis>
          <xyz>0.000000 1.000000 0.000000</xyz>
          <limit>
            <lower>0.000000</lower>
            <upper>0.000000</upper>
          </limit>
        </axis>
      </joint>
      <joint name='tilt_joint_right' type='revolute'>
        <pose>0.000000 0.000000 0.000000 0.000000 0.000000 0.000000</pose>
        <child>camera_column_body_right</child>
        <parent>camera_top_body_right</parent>
        <axis>
          <xyz>1.000000 0.000000 0.000000</xyz>
          <limit>
            <lower>0.000000</lower>
            <upper>0.000000</upper>
          </limit>
        </axis>
      </joint>
      <joint name='camera_right' type='revolute'>
        <pose>0.000000 0.000000 0.000000 0.000000 0.000000 0.000000</pose>
        <child>camera_bottom_body_right</child>
        <parent>chassis</parent>
        <axis>
          <xyz>0.000000 0.000000 0.000000</xyz>
          <limit>
            <lower>0.000000</lower>
            <upper>0.000000</upper>
          </limit>
        </axis>
      </joint>
      <joint name='pan_joint_left' type='revolute'>
        <pose>0.000000 0.000000 0.000000 0.000000 0.000000 0.000000</pose>
        <child>camera_bottom_body_left</child>
        <parent>camera_column_body_left</parent>
        <axis>
          <xyz>0.000000 1.000000 0.000000</xyz>
          <limit>
            <lower>0.000000</lower>
            <upper>0.000000</upper>
          </limit>
        </axis>
      </joint>
      <joint name='tilt_joint_left' type='revolute'>
        <pose>0.000000 0.000000 0.000000 0.000000 0.000000 0.000000</pose>
        <child>camera_column_body_left</child>
        <parent>camera_top_body_left</parent>
        <axis>
          <xyz>1.000000 0.000000 0.000000</xyz>
          <limit>
            <lower>0.000000</lower>
            <upper>0.000000</upper>
          </limit>
        </axis>
      </joint>
      <joint name='camera_left' type='revolute'>
        <pose>0.000000 0.000000 0.000000 0.000000 0.000000 0.000000</pose>
        <child>camera_bottom_body_left</child>
        <parent>chassis</parent>
        <axis>
          <xyz>0.000000 0.000000 0.000000</xyz>
          <limit>
            <lower>0.000000</lower>
            <upper>0.000000</upper>
          </limit>
        </axis>
      </joint>
      <joint name='left_wheel_hinge' type='revolute'>
        <pose>0.000000 0.000000 -0.030000 0.000000 0.000000 0.000000</pose>
        <child>left_wheel</child>
        <parent>chassis</parent>
        <axis>
          <xyz>0.000000 1.000000 0.000000</xyz>
          <limit>
            <lower>-10000000000000000.000000</lower>
            <upper>10000000000000000.000000</upper>
          </limit>
        </axis>
      </joint>
      <joint name='right_wheel_hinge' type='revolute'>
        <pose>0.000000 0.000000 0.030000 0.000000 0.000000 0.000000</pose>
        <child>right_wheel</child>
        <parent>chassis</parent>
        <axis>
          <xyz>0.000000 1.000000 0.000000</xyz>
          <limit>
            <lower>-10000000000000000.000000</lower>
            <upper>10000000000000000.000000</upper>
          </limit>
        </axis>
      </joint>
      <joint name='joint_laser' type='revolute'>
        <parent>chassis</parent>
        <child>laser</child>
        <axis>
          <xyz>0.000000 0.000000 0.000000</xyz>
          <limit>
            <lower>0.000000</lower>
            <upper>0.000000</upper>
          </limit>
        </axis>
      </joint>
      <plugin name='motors' filename='libmotors.so'>
        <left_joint>left_wheel_hinge</left_joint>
        <right_joint>right_wheel_hinge</right_joint>
        <torque>5</torque>
      </plugin>
      <plugin name='pose3dencoders' filename='libpose3dencoders.so'>
        <left_joint_pose3dencoders_pan>pan_joint_right</left_joint_pose3dencoders_pan>
        <left_joint_pose3dencoders_tilt>tilt_joint_right</left_joint_pose3dencoders_tilt>
        <right_joint_pose3dencoders_pan>pan_joint_left</right_joint_pose3dencoders_pan>
        <right_joint_pose3dencoders_tilt>tilt_joint_left</right_joint_pose3dencoders_tilt>
        <torque>5</torque>
      </plugin>
      <plugin name='encoders' filename='libencoders.so'/>
      <static>0</static>
    </model>
    <light name='sun' type='directional'>
      <cast_shadows>1</cast_shadows>
      <pose>0.000000 0.000000 10.000000 0.000000 0.000000 0.000000</pose>
      <diffuse>0.800000 0.800000 0.800000 1.000000</diffuse>
      <specular>0.100000 0.100000 0.100000 1.000000</specular>
      <attenuation>
        <range>1000.000000</range>
        <constant>0.900000</constant>
        <linear>0.010000</linear>
        <quadratic>0.001000</quadratic>
      </attenuation>
      <direction>-0.500000 0.500000 -1.000000</direction>
    </light>
    <physics type='ode'>
      <max_step_size>0.001000</max_step_size>
      <real_time_factor>1.000000</real_time_factor>
      <real_time_update_rate>1000.000000</real_time_update_rate>
      <gravity>0.000000 0.000000 -9.800000</gravity>
      <max_contacts>20</max_contacts>
    </physics>
    <scene>
      <ambient>0.200000 0.200000 0.200000 1.000000</ambient>
      <background>0.700000 0.700000 0.700000 1.000000</background>
      <shadows>1</shadows>
    </scene>
    <model name='CircuitoMontmelo'>
      <static>1</static>
      <link name='link'>
        <collision name='collision'>
          <geometry>
            <box>
              <size>20.000000 20.000000 0.010000</size>
            </box>
          </geometry>
          <max_contacts>10</max_contacts>
          <surface>
            <bounce/>
            <friction>
              <ode/>
            </friction>
            <contact>
              <ode/>
            </contact>
          </surface>
        </collision>
        <visual name='visual'>
          <cast_shadows>0</cast_shadows>
          <geometry>
            <box>
              <size>20.000000 20.000000 0.010000</size>
            </box>
          </geometry>
          <material>
            <script>
              <uri>model://circuitoMontmelo/materials/scripts</uri>
              <uri>model://circuitoMontmelo/materials/textures</uri>
              <name>floor</name>
            </script>
          </material>
        </visual>
        <velocity_decay>
          <linear>0.000000</linear>
          <angular>0.000000</angular>
        </velocity_decay>
        <self_collide>0</self_collide>
        <kinematic>0</kinematic>
        <gravity>1</gravity>
      </link>
      <pose>1.000000 -3.000000 0.000000 0.000000 0.000000 0.000000</pose>
    </model>
    <state world_name='default'>
      <sim_time>128 197000000</sim_time>
      <real_time>129 57189687</real_time>
      <wall_time>1396537567 133021016</wall_time>
      <model name='pioneer2dx'>
        <pose>0.094746 -0.010508 0.004986 0.000136 0.000082 0.053893</pose>
        <link name='camera_bottom_body_left'>
          <pose>0.249154 0.097926 0.304986 -1.569860 0.000083 0.053893</pose>
          <velocity>0.001157 0.000067 0.002127 -0.000023 0.000310 -0.000495</velocity>
          <acceleration>0.000000 0.000000 0.000000 0.000000 0.000000 0.000000</acceleration>
          <wrench>0.000000 0.000000 0.000000 0.000000 0.000000 0.000000</wrench>
        </link>
        <link name='camera_bottom_body_right'>
          <pose>0.259927 -0.101783 0.304959 -1.569860 0.000083 0.053893</pose>
          <velocity>0.001086 0.000062 0.002359 -0.000380 0.000519 -0.000496</velocity>
          <acceleration>0.000000 0.000000 0.000000 0.000000 0.000000 0.000000</acceleration>
          <wrench>0.000000 0.000000 0.000000 0.000000 0.000000 0.000000</wrench>
        </link>
        <link name='camera_column_body_left'>
          <pose>0.259141 0.098463 0.319986 -1.569860 0.000083 0.053893</pose>
          <velocity>0.001161 0.000062 0.002115 -0.000022 0.000307 -0.000495</velocity>
          <acceleration>0.000000 0.000000 0.000000 0.000000 0.000000 0.000000</acceleration>
          <wrench>0.000000 0.000000 0.000000 0.000000 0.000000 0.000000</wrench>
        </link>
        <link name='camera_column_body_right'>
          <pose>0.269914 -0.101247 0.319958 -1.569860 0.000083 0.053893</pose>
          <velocity>0.001091 0.000058 0.002079 -0.000356 0.000476 -0.000497</velocity>
          <acceleration>0.000000 0.000000 0.000000 0.000000 0.000000 0.000000</acceleration>
          <wrench>0.000000 0.000000 0.000000 0.000000 0.000000 0.000000</wrench>
        </link>
        <link name='camera_top_body_left'>
          <pose>0.229184 0.096848 0.314988 -1.570140 -0.000084 -3.089290</pose>
          <velocity>0.001160 0.000078 0.002182 -0.000009 0.000321 -0.000495</velocity>
          <acceleration>0.000000 0.000000 0.000000 0.000000 0.000000 0.000000</acceleration>
          <wrench>0.000000 0.000000 0.000000 0.000000 0.000000 0.000000</wrench>
        </link>
        <link name='camera_top_body_right'>
          <pose>0.239957 -0.102862 0.314960 -1.570140 -0.000084 -3.089290</pose>
          <velocity>0.001087 0.000070 0.001878 -0.000258 0.000448 -0.000497</velocity>
          <acceleration>0.000000 0.000000 0.000000 0.000000 0.000000 0.000000</acceleration>
          <wrench>0.000000 0.000000 0.000000 0.000000 0.000000 0.000000</wrench>
        </link>
        <link name='chassis'>
          <pose>0.094760 -0.010529 0.164986 0.000136 0.000082 0.053893</pose>
          <velocity>0.001055 0.000101 0.002466 -0.000317 0.000551 -0.000494</velocity>
          <acceleration>0.000000 0.000000 0.000000 0.000000 0.000000 0.000000</acceleration>
          <wrench>0.000000 0.000000 0.000000 0.000000 0.000000 0.000000</wrench>
        </link>
        <link name='laser'>
          <pose>0.314454 0.001304 0.304968 0.000136 0.000083 0.053893</pose>
          <velocity>0.001133 0.000027 0.002243 -0.000441 0.000477 -0.000496</velocity>
          <acceleration>0.000000 0.000000 0.000000 0.000000 0.000000 0.000000</acceleration>
          <wrench>0.000000 0.000000 0.000000 0.000000 0.000000 0.000000</wrench>
        </link>
        <link name='left_wheel'>
          <pose>0.185454 0.164618 0.115004 1.570550 0.904308 -3.088030</pose>
          <velocity>0.001077 0.000067 0.002584 -0.000807 0.009039 -0.000491</velocity>
          <acceleration>0.000000 0.000000 0.000000 0.000000 0.000000 0.000000</acceleration>
          <wrench>0.000000 0.000000 0.000000 0.000000 0.000000 0.000000</wrench>
        </link>
        <link name='right_wheel'>
          <pose>0.203767 -0.174889 0.115004 1.570620 0.746642 -3.087960</pose>
          <velocity>0.000941 0.000057 0.009434 -0.000760 0.008124 -0.000495</velocity>
          <acceleration>0.000000 0.000000 0.000000 0.000000 0.000000 0.000000</acceleration>
          <wrench>0.000000 0.000000 0.000000 0.000000 0.000000 0.000000</wrench>
        </link>
      </model>
    </state>
    <model name='ParedesMontmelo'>
      <link name='Wall_23'>
        <collision name='Wall_23_Collision'>
          <geometry>
            <box>
              <size>3.240240 0.200000 2.500000</size>
            </box>
          </geometry>
          <pose>0.000000 0.000000 1.250000 0.000000 0.000000 0.000000</pose>
          <max_contacts>10</max_contacts>
          <surface>
            <bounce/>
            <friction>
              <ode/>
            </friction>
            <contact>
              <ode/>
            </contact>
          </surface>
        </collision>
        <visual name='Wall_23_Visual'>
          <pose>0.000000 0.000000 1.250000 0.000000 0.000000 0.000000</pose>
          <geometry>
            <box>
              <size>3.240240 0.200000 2.500000</size>
            </box>
          </geometry>
          <material>
            <script>
              <uri>file://media/materials/scripts/gazebo.material</uri>
              <name>Gazebo/Grey</name>
            </script>
          </material>
        </visual>
        <velocity_decay>
          <linear>0.000000</linear>
          <angular>0.000000</angular>
        </velocity_decay>
        <pose>-4.624190 5.629750 0.000000 0.000000 0.000000 0.495133</pose>
        <self_collide>0</self_collide>
        <kinematic>0</kinematic>
        <gravity>1</gravity>
      </link>
      <link name='Wall_24'>
        <collision name='Wall_24_Collision'>
          <geometry>
            <box>
              <size>1.421220 0.200000 2.500000</size>
            </box>
          </geometry>
          <pose>0.000000 0.000000 1.250000 0.000000 0.000000 0.000000</pose>
          <max_contacts>10</max_contacts>
          <surface>
            <bounce/>
            <friction>
              <ode/>
            </friction>
            <contact>
              <ode/>
            </contact>
          </surface>
        </collision>
        <visual name='Wall_24_Visual'>
          <pose>0.000000 0.000000 1.250000 0.000000 0.000000 0.000000</pose>
          <geometry>
            <box>
              <size>1.421220 0.200000 2.500000</size>
            </box>
          </geometry>
          <material>
            <script>
              <uri>file://media/materials/scripts/gazebo.material</uri>
              <name>Gazebo/Grey</name>
            </script>
          </material>
        </visual>
        <velocity_decay>
          <linear>0.000000</linear>
          <angular>0.000000</angular>
        </velocity_decay>
        <pose>-2.751600 6.646300 0.000000 0.000000 0.000000 0.502843</pose>
        <self_collide>0</self_collide>
        <kinematic>0</kinematic>
        <gravity>1</gravity>
      </link>
      <link name='Wall_25'>
        <collision name='Wall_25_Collision'>
          <geometry>
            <box>
              <size>1.525650 0.200000 2.500000</size>
            </box>
          </geometry>
          <pose>0.000000 0.000000 1.250000 0.000000 0.000000 0.000000</pose>
          <max_contacts>10</max_contacts>
          <surface>
            <bounce/>
            <friction>
              <ode/>
            </friction>
            <contact>
              <ode/>
            </contact>
          </surface>
        </collision>
        <visual name='Wall_25_Visual'>
          <pose>0.000000 0.000000 1.250000 0.000000 0.000000 0.000000</pose>
          <geometry>
            <box>
              <size>1.525650 0.200000 2.500000</size>
            </box>
          </geometry>
          <material>
            <script>
              <uri>file://media/materials/scripts/gazebo.material</uri>
              <name>Gazebo/Grey</name>
            </script>
          </material>
        </visual>
        <velocity_decay>
          <linear>0.000000</linear>
          <angular>0.000000</angular>
        </velocity_decay>
        <pose>-1.663700 7.306160 0.000000 0.000000 0.000000 0.584242</pose>
        <self_collide>0</self_collide>
        <kinematic>0</kinematic>
        <gravity>1</gravity>
      </link>
      <link name='Wall_26'>
        <collision name='Wall_26_Collision'>
          <geometry>
            <box>
              <size>1.573160 0.200000 2.500000</size>
            </box>
          </geometry>
          <pose>0.000000 0.000000 1.250000 0.000000 0.000000 0.000000</pose>
          <max_contacts>10</max_contacts>
          <surface>
            <bounce/>
            <friction>
              <ode/>
            </friction>
            <contact>
              <ode/>
            </contact>
          </surface>
        </collision>
        <visual name='Wall_26_Visual'>
          <pose>0.000000 0.000000 1.250000 0.000000 0.000000 0.000000</pose>
          <geometry>
            <box>
              <size>1.573160 0.200000 2.500000</size>
            </box>
          </geometry>
          <material>
            <script>
              <uri>file://media/materials/scripts/gazebo.material</uri>
              <name>Gazebo/Grey</name>
            </script>
          </material>
        </visual>
        <velocity_decay>
          <linear>0.000000</linear>
          <angular>0.000000</angular>
        </velocity_decay>
        <pose>-0.544373 8.059740 0.000000 0.000000 0.000000 0.600567</pose>
        <self_collide>0</self_collide>
        <kinematic>0</kinematic>
        <gravity>1</gravity>
      </link>
      <link name='Wall_27'>
        <collision name='Wall_27_Collision'>
          <geometry>
            <box>
              <size>6.143590 0.200000 2.500000</size>
            </box>
          </geometry>
          <pose>0.000000 0.000000 1.250000 0.000000 0.000000 0.000000</pose>
          <max_contacts>10</max_contacts>
          <surface>
            <bounce/>
            <friction>
              <ode/>
            </friction>
            <contact>
              <ode/>
            </contact>
          </surface>
        </collision>
        <visual name='Wall_27_Visual'>
          <pose>0.000000 0.000000 1.250000 0.000000 0.000000 0.000000</pose>
          <geometry>
            <box>
              <size>6.143590 0.200000 2.500000</size>
            </box>
          </geometry>
          <material>
            <script>
              <uri>file://media/materials/scripts/gazebo.material</uri>
              <name>Gazebo/Grey</name>
            </script>
          </material>
        </visual>
        <velocity_decay>
          <linear>0.000000</linear>
          <angular>0.000000</angular>
        </velocity_decay>
        <pose>2.993860 8.447740 0.000000 0.000000 0.000000 0.000000</pose>
        <self_collide>0</self_collide>
        <kinematic>0</kinematic>
        <gravity>1</gravity>
      </link>
      <link name='Wall_29'>
        <collision name='Wall_29_Collision'>
          <geometry>
            <box>
              <size>2.356640 0.200000 2.500000</size>
            </box>
          </geometry>
          <pose>0.000000 0.000000 1.250000 0.000000 0.000000 0.000000</pose>
          <max_contacts>10</max_contacts>
          <surface>
            <bounce/>
            <friction>
              <ode/>
            </friction>
            <contact>
              <ode/>
            </contact>
          </surface>
        </collision>
        <visual name='Wall_29_Visual'>
          <pose>0.000000 0.000000 1.250000 0.000000 0.000000 0.000000</pose>
          <geometry>
            <box>
              <size>2.356640 0.200000 2.500000</size>
            </box>
          </geometry>
          <material>
            <script>
              <uri>file://media/materials/scripts/gazebo.material</uri>
              <name>Gazebo/Grey</name>
            </script>
          </material>
        </visual>
        <velocity_decay>
          <linear>0.000000</linear>
          <angular>0.000000</angular>
        </velocity_decay>
        <pose>6.743990 7.563270 0.000000 0.000000 0.000000 -0.855053</pose>
        <self_collide>0</self_collide>
        <kinematic>0</kinematic>
        <gravity>1</gravity>
      </link>
      <link name='Wall_30'>
        <collision name='Wall_30_Collision'>
          <geometry>
            <box>
              <size>5.213800 0.200000 2.500000</size>
            </box>
          </geometry>
          <pose>0.000000 0.000000 1.250000 0.000000 0.000000 0.000000</pose>
          <max_contacts>10</max_contacts>
          <surface>
            <bounce/>
            <friction>
              <ode/>
            </friction>
            <contact>
              <ode/>
            </contact>
          </surface>
        </collision>
        <visual name='Wall_30_Visual'>
          <pose>0.000000 0.000000 1.250000 0.000000 0.000000 0.000000</pose>
          <geometry>
            <box>
              <size>5.213800 0.200000 2.500000</size>
            </box>
          </geometry>
          <material>
            <script>
              <uri>file://media/materials/scripts/gazebo.material</uri>
              <name>Gazebo/Grey</name>
            </script>
          </material>
        </visual>
        <velocity_decay>
          <linear>0.000000</linear>
          <angular>0.000000</angular>
        </velocity_decay>
        <pose>7.492240 4.243000 0.000000 0.000000 0.000000 -1.554570</pose>
        <self_collide>0</self_collide>
        <kinematic>0</kinematic>
        <gravity>1</gravity>
      </link>
      <link name='Wall_31'>
        <collision name='Wall_31_Collision'>
          <geometry>
            <box>
              <size>2.004890 0.200000 2.500000</size>
            </box>
          </geometry>
          <pose>0.000000 0.000000 1.250000 0.000000 0.000000 0.000000</pose>
          <max_contacts>10</max_contacts>
          <surface>
            <bounce/>
            <friction>
              <ode/>
            </friction>
            <contact>
              <ode/>
            </contact>
          </surface>
        </collision>
        <visual name='Wall_31_Visual'>
          <pose>0.000000 0.000000 1.250000 0.000000 0.000000 0.000000</pose>
          <geometry>
            <box>
              <size>2.004890 0.200000 2.500000</size>
            </box>
          </geometry>
          <material>
            <script>
              <uri>file://media/materials/scripts/gazebo.material</uri>
              <name>Gazebo/Grey</name>
            </script>
          </material>
        </visual>
        <velocity_decay>
          <linear>0.000000</linear>
          <angular>0.000000</angular>
        </velocity_decay>
        <pose>6.983550 1.020470 0.000000 0.000000 0.000000 -2.225300</pose>
        <self_collide>0</self_collide>
        <kinematic>0</kinematic>
        <gravity>1</gravity>
      </link>
      <link name='Wall_33'>
        <collision name='Wall_33_Collision'>
          <geometry>
            <box>
              <size>2.434360 0.200000 2.500000</size>
            </box>
          </geometry>
          <pose>0.000000 0.000000 1.250000 0.000000 0.000000 0.000000</pose>
          <max_contacts>10</max_contacts>
          <surface>
            <bounce/>
            <friction>
              <ode/>
            </friction>
            <contact>
              <ode/>
            </contact>
          </surface>
        </collision>
        <visual name='Wall_33_Visual'>
          <pose>0.000000 0.000000 1.250000 0.000000 0.000000 0.000000</pose>
          <geometry>
            <box>
              <size>2.434360 0.200000 2.500000</size>
            </box>
          </geometry>
          <material>
            <script>
              <uri>file://media/materials/scripts/gazebo.material</uri>
              <name>Gazebo/Grey</name>
            </script>
          </material>
        </visual>
        <velocity_decay>
          <linear>0.000000</linear>
          <angular>0.000000</angular>
        </velocity_decay>
        <pose>-5.347530 -12.147000 0.000000 0.000000 0.000000 -0.992894</pose>
        <self_collide>0</self_collide>
        <kinematic>0</kinematic>
        <gravity>1</gravity>
      </link>
      <link name='Wall_34'>
        <collision name='Wall_34_Collision'>
          <geometry>
            <box>
              <size>2.531520 0.200000 2.500000</size>
            </box>
          </geometry>
          <pose>0.000000 0.000000 1.250000 0.000000 0.000000 0.000000</pose>
          <max_contacts>10</max_contacts>
          <surface>
            <bounce/>
            <friction>
              <ode/>
            </friction>
            <contact>
              <ode/>
            </contact>
          </surface>
        </collision>
        <visual name='Wall_34_Visual'>
          <pose>0.000000 0.000000 1.250000 0.000000 0.000000 0.000000</pose>
          <geometry>
            <box>
              <size>2.531520 0.200000 2.500000</size>
            </box>
          </geometry>
          <material>
            <script>
              <uri>file://media/materials/scripts/gazebo.material</uri>
              <name>Gazebo/Grey</name>
            </script>
          </material>
        </visual>
        <velocity_decay>
          <linear>0.000000</linear>
          <angular>0.000000</angular>
        </velocity_decay>
        <pose>-3.720120 -13.652400 0.000000 0.000000 0.000000 -0.510488</pose>
        <self_collide>0</self_collide>
        <kinematic>0</kinematic>
        <gravity>1</gravity>
      </link>
      <link name='Wall_35'>
        <collision name='Wall_35_Collision'>
          <geometry>
            <box>
              <size>4.268530 0.200000 2.500000</size>
            </box>
          </geometry>
          <pose>0.000000 0.000000 1.250000 0.000000 0.000000 0.000000</pose>
          <max_contacts>10</max_contacts>
          <surface>
            <bounce/>
            <friction>
              <ode/>
            </friction>
            <contact>
              <ode/>
            </contact>
          </surface>
        </collision>
        <visual name='Wall_35_Visual'>
          <pose>0.000000 0.000000 1.250000 0.000000 0.000000 0.000000</pose>
          <geometry>
            <box>
              <size>4.268530 0.200000 2.500000</size>
            </box>
          </geometry>
          <material>
            <script>
              <uri>file://media/materials/scripts/gazebo.material</uri>
              <name>Gazebo/Grey</name>
            </script>
          </material>
        </visual>
        <velocity_decay>
          <linear>0.000000</linear>
          <angular>0.000000</angular>
        </velocity_decay>
        <pose>-0.668718 -14.222000 0.000000 0.000000 0.000000 0.000000</pose>
        <self_collide>0</self_collide>
        <kinematic>0</kinematic>
        <gravity>1</gravity>
      </link>
      <link name='Wall_36'>
        <collision name='Wall_36_Collision'>
          <geometry>
            <box>
              <size>0.950200 0.200000 2.500000</size>
            </box>
          </geometry>
          <pose>0.000000 0.000000 1.250000 0.000000 0.000000 0.000000</pose>
          <max_contacts>10</max_contacts>
          <surface>
            <bounce/>
            <friction>
              <ode/>
            </friction>
            <contact>
              <ode/>
            </contact>
          </surface>
        </collision>
        <visual name='Wall_36_Visual'>
          <pose>0.000000 0.000000 1.250000 0.000000 0.000000 0.000000</pose>
          <geometry>
            <box>
              <size>0.950200 0.200000 2.500000</size>
            </box>
          </geometry>
          <material>
            <script>
              <uri>file://media/materials/scripts/gazebo.material</uri>
              <name>Gazebo/Grey</name>
            </script>
          </material>
        </visual>
        <velocity_decay>
          <linear>0.000000</linear>
          <angular>0.000000</angular>
        </velocity_decay>
        <pose>1.609660 -13.937200 0.000000 0.000000 0.000000 0.862170</pose>
        <self_collide>0</self_collide>
        <kinematic>0</kinematic>
        <gravity>1</gravity>
      </link>
      <link name='Wall_37'>
        <collision name='Wall_37_Collision'>
          <geometry>
            <box>
              <size>3.802430 0.200000 2.500000</size>
            </box>
          </geometry>
          <pose>0.000000 0.000000 1.250000 0.000000 0.000000 0.000000</pose>
          <max_contacts>10</max_contacts>
          <surface>
            <bounce/>
            <friction>
              <ode/>
            </friction>
            <contact>
              <ode/>
            </contact>
          </surface>
        </collision>
        <visual name='Wall_37_Visual'>
          <pose>0.000000 0.000000 1.250000 0.000000 0.000000 0.000000</pose>
          <geometry>
            <box>
              <size>3.802430 0.200000 2.500000</size>
            </box>
          </geometry>
          <material>
            <script>
              <uri>file://media/materials/scripts/gazebo.material</uri>
              <name>Gazebo/Grey</name>
            </script>
          </material>
        </visual>
        <velocity_decay>
          <linear>0.000000</linear>
          <angular>0.000000</angular>
        </velocity_decay>
        <pose>3.562550 -13.082800 0.000000 0.000000 0.000000 0.321751</pose>
        <self_collide>0</self_collide>
        <kinematic>0</kinematic>
        <gravity>1</gravity>
      </link>
      <link name='Wall_38'>
        <collision name='Wall_38_Collision'>
          <geometry>
            <box>
              <size>4.076010 0.200000 2.500000</size>
            </box>
          </geometry>
          <pose>0.000000 0.000000 1.250000 0.000000 0.000000 0.000000</pose>
          <max_contacts>10</max_contacts>
          <surface>
            <bounce/>
            <friction>
              <ode/>
            </friction>
            <contact>
              <ode/>
            </contact>
          </surface>
        </collision>
        <visual name='Wall_38_Visual'>
          <pose>0.000000 0.000000 1.250000 0.000000 0.000000 0.000000</pose>
          <geometry>
            <box>
              <size>4.076010 0.200000 2.500000</size>
            </box>
          </geometry>
          <material>
            <script>
              <uri>file://media/materials/scripts/gazebo.material</uri>
              <name>Gazebo/Grey</name>
            </script>
          </material>
        </visual>
        <velocity_decay>
          <linear>0.000000</linear>
          <angular>0.000000</angular>
        </velocity_decay>
        <pose>6.491900 -11.007800 0.000000 0.000000 0.000000 0.889498</pose>
        <self_collide>0</self_collide>
        <kinematic>0</kinematic>
        <gravity>1</gravity>
      </link>
      <link name='Wall_39'>
        <collision name='Wall_39_Collision'>
          <geometry>
            <box>
              <size>2.478380 0.200000 2.500000</size>
            </box>
          </geometry>
          <pose>0.000000 0.000000 1.250000 0.000000 0.000000 0.000000</pose>
          <max_contacts>10</max_contacts>
          <surface>
            <bounce/>
            <friction>
              <ode/>
            </friction>
            <contact>
              <ode/>
            </contact>
          </surface>
        </collision>
        <visual name='Wall_39_Visual'>
          <pose>0.000000 0.000000 1.250000 0.000000 0.000000 0.000000</pose>
          <geometry>
            <box>
              <size>2.478380 0.200000 2.500000</size>
            </box>
          </geometry>
          <material>
            <script>
              <uri>file://media/materials/scripts/gazebo.material</uri>
              <name>Gazebo/Grey</name>
            </script>
          </material>
        </visual>
        <velocity_decay>
          <linear>0.000000</linear>
          <angular>0.000000</angular>
        </velocity_decay>
        <pose>7.712460 -8.363270 0.000000 0.000000 0.000000 1.570800</pose>
        <self_collide>0</self_collide>
        <kinematic>0</kinematic>
        <gravity>1</gravity>
      </link>
      <link name='Wall_40'>
        <collision name='Wall_40_Collision'>
          <geometry>
            <box>
              <size>1.947100 0.200000 2.500000</size>
            </box>
          </geometry>
          <pose>0.000000 0.000000 1.250000 0.000000 0.000000 0.000000</pose>
          <max_contacts>10</max_contacts>
          <surface>
            <bounce/>
            <friction>
              <ode/>
            </friction>
            <contact>
              <ode/>
            </contact>
          </surface>
        </collision>
        <visual name='Wall_40_Visual'>
          <pose>0.000000 0.000000 1.250000 0.000000 0.000000 0.000000</pose>
          <geometry>
            <box>
              <size>1.947100 0.200000 2.500000</size>
            </box>
          </geometry>
          <material>
            <script>
              <uri>file://media/materials/scripts/gazebo.material</uri>
              <name>Gazebo/Grey</name>
            </script>
          </material>
        </visual>
        <velocity_decay>
          <linear>0.000000</linear>
          <angular>0.000000</angular>
        </velocity_decay>
        <pose>6.939430 -6.817220 0.000000 0.000000 0.000000 2.657120</pose>
        <self_collide>0</self_collide>
        <kinematic>0</kinematic>
        <gravity>1</gravity>
      </link>
      <link name='Wall_41'>
        <collision name='Wall_41_Collision'>
          <geometry>
            <box>
              <size>1.583300 0.200000 2.500000</size>
            </box>
          </geometry>
          <pose>0.000000 0.000000 1.250000 0.000000 0.000000 0.000000</pose>
          <max_contacts>10</max_contacts>
          <surface>
            <bounce/>
            <friction>
              <ode/>
            </friction>
            <contact>
              <ode/>
            </contact>
          </surface>
        </collision>
        <visual name='Wall_41_Visual'>
          <pose>0.000000 0.000000 1.250000 0.000000 0.000000 0.000000</pose>
          <geometry>
            <box>
              <size>1.583300 0.200000 2.500000</size>
            </box>
          </geometry>
          <material>
            <script>
              <uri>file://media/materials/scripts/gazebo.material</uri>
              <name>Gazebo/Grey</name>
            </script>
          </material>
        </visual>
        <velocity_decay>
          <linear>0.000000</linear>
          <angular>0.000000</angular>
        </velocity_decay>
        <pose>5.474760 -6.410370 0.000000 0.000000 0.000000 3.141590</pose>
        <self_collide>0</self_collide>
        <kinematic>0</kinematic>
        <gravity>1</gravity>
      </link>
      <link name='Wall_42'>
        <collision name='Wall_42_Collision'>
          <geometry>
            <box>
              <size>1.473650 0.200000 2.500000</size>
            </box>
          </geometry>
          <pose>0.000000 0.000000 1.250000 0.000000 0.000000 0.000000</pose>
          <max_contacts>10</max_contacts>
          <surface>
            <bounce/>
            <friction>
              <ode/>
            </friction>
            <contact>
              <ode/>
            </contact>
          </surface>
        </collision>
        <visual name='Wall_42_Visual'>
          <pose>0.000000 0.000000 1.250000 0.000000 0.000000 0.000000</pose>
          <geometry>
            <box>
              <size>1.473650 0.200000 2.500000</size>
            </box>
          </geometry>
          <material>
            <script>
              <uri>file://media/materials/scripts/gazebo.material</uri>
              <name>Gazebo/Grey</name>
            </script>
          </material>
        </visual>
        <velocity_decay>
          <linear>0.000000</linear>
          <angular>0.000000</angular>
        </velocity_decay>
        <pose>4.231610 -6.728780 0.000000 0.000000 0.000000 -2.617990</pose>
        <self_collide>0</self_collide>
        <kinematic>0</kinematic>
        <gravity>1</gravity>
      </link>
      <link name='Wall_44'>
        <collision name='Wall_44_Collision'>
          <geometry>
            <box>
              <size>5.961250 0.200000 2.500000</size>
            </box>
          </geometry>
          <pose>0.000000 0.000000 1.250000 0.000000 0.000000 0.000000</pose>
          <max_contacts>10</max_contacts>
          <surface>
            <bounce/>
            <friction>
              <ode/>
            </friction>
            <contact>
              <ode/>
            </contact>
          </surface>
        </collision>
        <visual name='Wall_44_Visual'>
          <pose>0.000000 0.000000 1.250000 0.000000 0.000000 0.000000</pose>
          <geometry>
            <box>
              <size>5.961250 0.200000 2.500000</size>
            </box>
          </geometry>
          <material>
            <script>
              <uri>file://media/materials/scripts/gazebo.material</uri>
              <name>Gazebo/Grey</name>
            </script>
          </material>
        </visual>
        <velocity_decay>
          <linear>0.000000</linear>
          <angular>0.000000</angular>
        </velocity_decay>
        <pose>6.736010 -3.847200 0.000000 0.000000 0.000000 0.935770</pose>
        <self_collide>0</self_collide>
        <kinematic>0</kinematic>
        <gravity>1</gravity>
      </link>
      <link name='Wall_45'>
        <collision name='Wall_45_Collision'>
          <geometry>
            <box>
              <size>3.066510 0.200000 2.500000</size>
            </box>
          </geometry>
          <pose>0.000000 0.000000 1.250000 0.000000 0.000000 0.000000</pose>
          <max_contacts>10</max_contacts>
          <surface>
            <bounce/>
            <friction>
              <ode/>
            </friction>
            <contact>
              <ode/>
            </contact>
          </surface>
        </collision>
        <visual name='Wall_45_Visual'>
          <pose>0.000000 0.000000 1.250000 0.000000 0.000000 0.000000</pose>
          <geometry>
            <box>
              <size>3.066510 0.200000 2.500000</size>
            </box>
          </geometry>
          <material>
            <script>
              <uri>file://media/materials/scripts/gazebo.material</uri>
              <name>Gazebo/Grey</name>
            </script>
          </material>
        </visual>
        <velocity_decay>
          <linear>0.000000</linear>
          <angular>0.000000</angular>
        </velocity_decay>
        <pose>7.631080 -0.348260 0.000000 0.000000 0.000000 2.174550</pose>
        <self_collide>0</self_collide>
        <kinematic>0</kinematic>
        <gravity>1</gravity>
      </link>
      <link name='Wall_47'>
        <collision name='Wall_47_Collision'>
          <geometry>
            <box>
              <size>8.672580 0.200000 2.500000</size>
            </box>
          </geometry>
          <pose>0.000000 0.000000 1.250000 0.000000 0.000000 0.000000</pose>
          <max_contacts>10</max_contacts>
          <surface>
            <bounce/>
            <friction>
              <ode/>
            </friction>
            <contact>
              <ode/>
            </contact>
          </surface>
        </collision>
        <visual name='Wall_47_Visual'>
          <pose>0.000000 0.000000 1.250000 0.000000 0.000000 0.000000</pose>
          <geometry>
            <box>
              <size>8.672580 0.200000 2.500000</size>
            </box>
          </geometry>
          <material>
            <script>
              <uri>file://media/materials/scripts/gazebo.material</uri>
              <name>Gazebo/Grey</name>
            </script>
          </material>
        </visual>
        <velocity_decay>
          <linear>0.000000</linear>
          <angular>0.000000</angular>
        </velocity_decay>
        <pose>-2.214760 -6.006970 0.000000 0.000000 0.000000 1.570800</pose>
        <self_collide>0</self_collide>
        <kinematic>0</kinematic>
        <gravity>1</gravity>
      </link>
      <link name='Wall_49'>
        <collision name='Wall_49_Collision'>
          <geometry>
            <box>
              <size>8.675200 0.200000 2.500000</size>
            </box>
          </geometry>
          <pose>0.000000 0.000000 1.250000 0.000000 0.000000 0.000000</pose>
          <max_contacts>10</max_contacts>
          <surface>
            <bounce/>
            <friction>
              <ode/>
            </friction>
            <contact>
              <ode/>
            </contact>
          </surface>
        </collision>
        <visual name='Wall_49_Visual'>
          <pose>0.000000 0.000000 1.250000 0.000000 0.000000 0.000000</pose>
          <geometry>
            <box>
              <size>8.675200 0.200000 2.500000</size>
            </box>
          </geometry>
          <material>
            <script>
              <uri>file://media/materials/scripts/gazebo.material</uri>
              <name>Gazebo/Grey</name>
            </script>
          </material>
        </visual>
        <velocity_decay>
          <linear>0.000000</linear>
          <angular>0.000000</angular>
        </velocity_decay>
        <pose>0.481704 -5.402490 0.000000 0.000000 0.000000 0.916298</pose>
        <self_collide>0</self_collide>
        <kinematic>0</kinematic>
        <gravity>1</gravity>
      </link>
      <link name='Wall_51'>
        <collision name='Wall_51_Collision'>
          <geometry>
            <box>
              <size>5.489090 0.200000 2.500000</size>
            </box>
          </geometry>
          <pose>0.000000 0.000000 1.250000 0.000000 0.000000 0.000000</pose>
          <max_contacts>10</max_contacts>
          <surface>
            <bounce/>
            <friction>
              <ode/>
            </friction>
            <contact>
              <ode/>
            </contact>
          </surface>
        </collision>
        <visual name='Wall_51_Visual'>
          <pose>0.000000 0.000000 1.250000 0.000000 0.000000 0.000000</pose>
          <geometry>
            <box>
              <size>5.489090 0.200000 2.500000</size>
            </box>
          </geometry>
          <material>
            <script>
              <uri>file://media/materials/scripts/gazebo.material</uri>
              <name>Gazebo/Grey</name>
            </script>
          </material>
        </visual>
        <velocity_decay>
          <linear>0.000000</linear>
          <angular>0.000000</angular>
        </velocity_decay>
        <pose>0.511156 -2.016360 0.000000 0.000000 0.000000 0.000000</pose>
        <self_collide>0</self_collide>
        <kinematic>0</kinematic>
        <gravity>1</gravity>
      </link>
      <link name='Wall_53'>
        <collision name='Wall_53_Collision'>
          <geometry>
            <box>
              <size>1.148940 0.200000 2.500000</size>
            </box>
          </geometry>
          <pose>0.000000 0.000000 1.250000 0.000000 0.000000 0.000000</pose>
          <max_contacts>10</max_contacts>
          <surface>
            <bounce/>
            <friction>
              <ode/>
            </friction>
            <contact>
              <ode/>
            </contact>
          </surface>
        </collision>
        <visual name='Wall_53_Visual'>
          <pose>0.000000 0.000000 1.250000 0.000000 0.000000 0.000000</pose>
          <geometry>
            <box>
              <size>1.148940 0.200000 2.500000</size>
            </box>
          </geometry>
          <material>
            <script>
              <uri>file://media/materials/scripts/gazebo.material</uri>
              <name>Gazebo/Grey</name>
            </script>
          </material>
        </visual>
        <velocity_decay>
          <linear>0.000000</linear>
          <angular>0.000000</angular>
        </velocity_decay>
        <pose>-1.645160 -10.560300 0.000000 0.000000 0.000000 -0.540420</pose>
        <self_collide>0</self_collide>
        <kinematic>0</kinematic>
        <gravity>1</gravity>
      </link>
      <link name='Wall_55'>
        <collision name='Wall_55_Collision'>
          <geometry>
            <box>
              <size>0.858154 0.200000 2.500000</size>
            </box>
          </geometry>
          <pose>0.000000 0.000000 1.250000 0.000000 0.000000 0.000000</pose>
          <max_contacts>10</max_contacts>
          <surface>
            <bounce/>
            <friction>
              <ode/>
            </friction>
            <contact>
              <ode/>
            </contact>
          </surface>
        </collision>
        <visual name='Wall_55_Visual'>
          <pose>0.000000 0.000000 1.250000 0.000000 0.000000 0.000000</pose>
          <geometry>
            <box>
              <size>0.858154 0.200000 2.500000</size>
            </box>
          </geometry>
          <material>
            <script>
              <uri>file://media/materials/scripts/gazebo.material</uri>
              <name>Gazebo/Grey</name>
            </script>
          </material>
        </visual>
        <velocity_decay>
          <linear>0.000000</linear>
          <angular>0.000000</angular>
        </velocity_decay>
        <pose>4.091460 4.087510 0.000000 0.000000 0.000000 1.446840</pose>
        <self_collide>0</self_collide>
        <kinematic>0</kinematic>
        <gravity>1</gravity>
      </link>
      <link name='Wall_56'>
        <collision name='Wall_56_Collision'>
          <geometry>
            <box>
              <size>1.748180 0.200000 2.500000</size>
            </box>
          </geometry>
          <pose>0.000000 0.000000 1.250000 0.000000 0.000000 0.000000</pose>
          <max_contacts>10</max_contacts>
          <surface>
            <bounce/>
            <friction>
              <ode/>
            </friction>
            <contact>
              <ode/>
            </contact>
          </surface>
        </collision>
        <visual name='Wall_56_Visual'>
          <pose>0.000000 0.000000 1.250000 0.000000 0.000000 0.000000</pose>
          <geometry>
            <box>
              <size>1.748180 0.200000 2.500000</size>
            </box>
          </geometry>
          <material>
            <script>
              <uri>file://media/materials/scripts/gazebo.material</uri>
              <name>Gazebo/Grey</name>
            </script>
          </material>
        </visual>
        <velocity_decay>
          <linear>0.000000</linear>
          <angular>0.000000</angular>
        </velocity_decay>
        <pose>4.132150 3.639970 0.000000 0.000000 0.000000 -1.570800</pose>
        <self_collide>0</self_collide>
        <kinematic>0</kinematic>
        <gravity>1</gravity>
      </link>
      <link name='Wall_8'>
        <collision name='Wall_8_Collision'>
          <geometry>
            <box>
              <size>16.201000 0.200000 2.500000</size>
            </box>
          </geometry>
          <pose>0.000000 0.000000 1.250000 0.000000 0.000000 0.000000</pose>
          <max_contacts>10</max_contacts>
          <surface>
            <bounce/>
            <friction>
              <ode/>
            </friction>
            <contact>
              <ode/>
            </contact>
          </surface>
        </collision>
        <visual name='Wall_8_Visual'>
          <pose>0.000000 0.000000 1.250000 0.000000 0.000000 0.000000</pose>
          <geometry>
            <box>
              <size>16.201000 0.200000 2.500000</size>
            </box>
          </geometry>
          <material>
            <script>
              <uri>file://media/materials/scripts/gazebo.material</uri>
              <name>Gazebo/Grey</name>
            </script>
          </material>
        </visual>
        <velocity_decay>
          <linear>0.000000</linear>
          <angular>0.000000</angular>
        </velocity_decay>
        <pose>-5.982460 -3.140350 0.000000 0.000000 0.000000 1.570800</pose>
        <self_collide>0</self_collide>
        <kinematic>0</kinematic>
        <gravity>1</gravity>
      </link>
      <static>1</static>
    </model>
    <gui fullscreen='0'>
      <camera name='user_camera'>
        <pose>9.421830 7.635330 71.043200 0.000000 1.569800 -3.126990</pose>
        <view_controller>orbit</view_controller>
      </camera>
    </gui>
  </world>
</sdf>
